Workbook

Sheet ABC-to-ABC_Weekday
A1: Last Updated: | B1: 45345 | C1: Z1
A2: STATION | B2: COORDINATES | C2: 4400 | D2: 4402 | E2: 4420
A3: DE WILDT | B3: -25.624641315648187, 27.944111334913465 | C3: 0.19444444 | D3: 0.3125 | E3: 0.68402778
A4: TAILLARDSHOOP | B4: -25.617806769500547, 27.972401220150644 | C4: 0.19791667 | D4: 0.31597222 | E4: 0.6875
A5: GA-RANKUWA | B5: -25.619463521827942, 27.991787773598496 | C5: 0.2 | D5: 0.31805556 | E5: 0.68958333
A6: ROSSLYN | B6: -25.637700722357806, 28.094920182723996 | C6: 0.20833333 | D6: 0.32638889 | E6: 0.69791667
A7: WINTERSNEST | B7: -25.646665143468105, 28.128664081235527 | C7: 0.21180556 | D7: 0.32986111 | E7: 0.70138889
A8: WOLMERTON | B8: -25.656754583256834, 28.166308537943245 | C8: 0.21597222 | D8: 0.33402778 | E8: 0.70555556
A9: PRETORIA-N | B9: -25.672156912459837, 28.181972182122085 | C9: 0.21875 | D9: 0.33680556 | E9: 0.70833333
A10: MOUNTAIN VIEW | B10: -25.701154966265122, 28.1710407244521 | C10: 0.22361111 | D10: 0.34166667 | E10: 0.71319444
A11: HERCULES | B11: -25.724426332570793, 28.16740145328856 | C11: 0.22708333 | D11: 0.34513889 | E11: 0.71666667
A12: PRETORIA WES | B12: -25.75612607001734, 28.167454033423436 | C12: 0.23194444 | D12: 0.35 | E12: 0.72152778
A13: PRETORIA | B13: -25.75864361043285, 28.189866445989118 | C13: 0.23611111 | D13: 0.35416667 | E13: 0.72569444
A33: =SORT(A2:A14, ROW(A2:A14), 0)

Sheet PRETORIA - IRENE - KEMPTON PARK
B9: Train No. | C9: 0500 | D9: 502 | E9: 624 | F9: 604 | G9: 506 | H9: 626 | I9: 628 | J9: 512 | K9: 616 | L9: 630 | M9: 514 | N9: 632 | O9: 618 | P9: 516 | Q9: 634 | R9: 518 | S9: 636 | T9: 520 | U9: 638 | V9: 522 | W9: 620 | X9: 640 | Y9: 524 | Z9: 642 | AA9: 526 | AB9: 622 | AC9: 644 | AD9: 528 | AE9: 646 | AF9: 654 | AG9: 530
B10: PRETORIA | E10: 0.21527778 | F10: 0.23611111 | H10: 0.26388889 | I10: 0.3125 | K10: 0.34027778 | L10: 0.36458333 | N10: 0.41319444 | O10: 0.44791667 | Q10: 0.46180556 | S10: 0.51041667 | U10: 0.55902778 | W10: 0.60069444 | X10: 0.60763889 | Z10: 0.65625 | AB10: 0.70138889 | AC10: 0.71180556 | AE10: 0.76041667 | AF10: 0.80555556
B11: FONTEINE
B12: KLOOFSIG
B13: SPORTPARK | E13: 0.22361111 | F13: 0.24375 | H13: 0.27222222 | I13: 0.32083333 | K13: 0.34791667 | L13: 0.37291667 | N13: 0.42152778 | O13: 0.45555556 | Q13: 0.47013889 | S13: 0.51875 | U13: 0.56736111 | W13: 0.60833333 | X13: 0.61597222 | Z13: 0.66458333 | AB13: 0.70902778 | AC13: 0.72013889 | AE13: 0.76875 | AF13: 0.81388889
B14: CENTURION | E14: 0.22638889 | F14: 0.24652778 | H14: 0.275 | I14: 0.32361111 | K14: 0.35069444 | L14: 0.37569444 | N14: 0.42430556 | O14: 0.45833333 | Q14: 0.47291667 | S14: 0.52152778 | U14: 0.57013889 | W14: 0.61111111 | X14: 0.61875 | Z14: 0.66736111 | AB14: 0.71180556 | AC14: 0.72291667 | AE14: 0.77152778 | AF14: 0.81736111
B15: IRENE | E15: 0.23263889 | F15: 0.25208333 | H15: 0.28125 | I15: 0.32986111 | K15: 0.35625 | L15: 0.38194444 | N15: 0.43055556 | O15: 0.46388889 | Q15: 0.47916667 | S15: 0.52777778 | U15: 0.57638889 | W15: 0.61666667 | X15: 0.625 | Z15: 0.67361111 | AB15: 0.71736111 | AC15: 0.72916667 | AE15: 0.77777778 | AF15: 0.82291667
B16: PINEDENE
B17: OLIFANTSFONTEIN | F17: 0.26111111 | K17: 0.36527778 | O17: 0.47291667 | W17: 0.62569444 | AF17: 0.83333333
B18: OAKMOOR | F18: 0.26666667 | K18: 0.37083333 | O18: 0.47847222 | W18: 0.63125 | AF18: 0.83888889
B19: LERALLA | C19: 0.15277778 | D19: 0.21180556 | G19: 0.25694444 | J19: 0.32291667 | M19: 0.37152778 | P19: 0.44791667 | R19: 0.48958333 | T19: 0.55208333 | V19: 0.59375 | Y19: 0.65625 | AA19: 0.69791667 | AD19: 0.76041667 | AG19: 0.81597222
B20: LIMINDLELA | C20: 0.15694444 | D20: 0.21597222 | G20: 0.26111111 | J20: 0.32708333 | M20: 0.37569444 | P20: 0.45208333 | R20: 0.49375 | T20: 0.55625 | V20: 0.59791667 | Y20: 0.66041667 | AA20: 0.70208333 | AD20: 0.76458333 | AG20: 0.82013889
B21: TEMBISA | C21: 0.16111111 | D21: 0.22013889 | G21: 0.26527778 | J21: 0.33125 | M21: 0.37986111 | P21: 0.45625 | R21: 0.49791667 | T21: 0.56041667 | V21: 0.60208333 | Y21: 0.66458333 | AA21: 0.70625 | AD21: 0.76875 | AG21: 0.82430556
B22: KAALFONTEIN
B23: BIRCHLEIGH
B24: VAN RIEBEECKPARK
B25: KEMPTON PARK | C25: 0.17777778 | D25: 0.23680556 | F25: 0.27777778 | G25: 0.28194444 | J25: 0.34791667 | K25: 0.38194444 | M25: 0.39652778 | O25: 0.48958333 | P25: 0.47291667 | R25: 0.51458333 | T25: 0.57708333 | V25: 0.61875 | W25: 0.64236111 | Y25: 0.68125 | AA25: 0.72291667 | AB25: 0.74305556 | AD25: 0.78541667 | AF25: 0.85208333 | AG25: 0.84097222
B26: RHODESFIELD | C26: 0.18125 | D26: 0.24027778 | G26: 0.28541667 | J26: 0.35138889 | M26: 0.4 | P26: 0.47638889 | R26: 0.51805556 | T26: 0.58055556 | V26: 0.62222222 | Y26: 0.68472222 | AA26: 0.72638889 | AD26: 0.78888889 | AF26: 0.85486111 | AG26: 0.84444444
B27: ISANDO
B28: ELANDSFONTEIN
B29: RAVENSKLIP | C29: 0.18819444 | D29: 0.24722222 | G29: 0.29236111 | J29: 0.35902778 | M29: 0.40763889 | P29: 0.48402778 | R29: 0.52569444 | T29: 0.58819444 | V29: 0.62986111 | Y29: 0.69236111 | AA29: 0.73402778 | AD29: 0.79652778 | AF29: 0.85902778 | AG29: 0.85208333
B30: KNIGHTS
B31: GERMISTON | C31: 0.19791667 | D31: 0.25694444 | G31: 0.30208333 | J31: 0.36875 | M31: 0.41736111 | P31: 0.49375 | R31: 0.53541667 | T31: 0.59791667 | V31: 0.63958333 | Y31: 0.70208333 | AA31: 0.74375 | AD31: 0.80625 | AG31: 0.86180556
B43: Train No. | C43: 603 | D43: 501 | E43: 625 | F43: 505 | G43: 615 | H43: 627 | I43: 507 | J43: 629 | K43: 631 | L43: 617 | M43: 509 | N43: 633 | O43: 511 | P43: 635 | Q43: 619 | R43: 513 | S43: 637 | T43: 515 | U43: 639 | V43: 517 | W43: 641 | X43: 519 | Y43: 621 | Z43: 643 | AA43: 521 | AB43: 645 | AC43: 623 | AD43: 523 | AE43: 647 | AF43: 525
B44: GERMISTON | D44: 0.20486111 | F44: 0.27083333 | I44: 0.31944444 | M44: 0.39583333 | O44: 0.4375 | R44: 0.5 | T44: 0.54166667 | V44: 0.60416667 | X44: 0.64583333 | AA44: 0.70833333 | AD44: 0.76388889 | AF44: 0.81944444
B45: KNIGHTS
B46: RAVENSKLIP | D46: 0.21388889 | F46: 0.27986111 | I46: 0.32916667 | M46: 0.40555556 | O46: 0.44722222 | R46: 0.50972222 | T46: 0.55138889 | V46: 0.61319444 | X46: 0.65486111 | AA46: 0.71805556 | AD46: 0.77361111 | AF46: 0.82916667
B47: ELANDSFONTEIN | C47: 0.17361111
B48: ISANDO
B49: RHODESFIELD | C49: 0.17847222 | D49: 0.22222222 | F49: 0.28819444 | I49: 0.3375 | M49: 0.41388889 | O49: 0.45555556 | R49: 0.51805556 | T49: 0.55972222 | V49: 0.62152778 | X49: 0.66319444 | AA49: 0.72638889 | AD49: 0.78194444 | AF49: 0.8375
B50: KEMPTON PARK | C50: 0.18125 | D50: 0.22569444 | F50: 0.29166667 | G50: 0.28472222 | I50: 0.34097222 | L50: 0.39583333 | M50: 0.41736111 | O50: 0.45902778 | Q50: 0.5 | R50: 0.52152778 | T50: 0.56319444 | V50: 0.625 | X50: 0.66666667 | Y50: 0.64930556 | AA50: 0.72986111 | AC50: 0.75347222 | AD50: 0.78541667 | AF50: 0.84097222
B51: VAN RIEBEECKPARK
B52: BIRCHLEIGH
B53: KAALFONTEIN
B54: TEMBISA | D54: 0.24166667 | F54: 0.30763889 | I54: 0.35694444 | M54: 0.43333333 | O54: 0.475 | R54: 0.5375 | T54: 0.57916667 | V54: 0.64097222 | X54: 0.68263889 | AA54: 0.74583333 | AD54: 0.80138889 | AF54: 0.85694444
B55: LIMINDLELA | D55: 0.24583333 | F55: 0.31180556 | I55: 0.36111111 | M55: 0.4375 | O55: 0.47916667 | R55: 0.54166667 | T55: 0.58333333 | V55: 0.64513889 | X55: 0.68680556 | AA55: 0.75 | AD55: 0.80555556 | AF55: 0.86111111
B56: LERALLA | D56: 0.25 | F56: 0.31597222 | I56: 0.36527778 | M56: 0.44166667 | O56: 0.48333333 | R56: 0.54583333 | T56: 0.5875 | V56: 0.64930556 | X56: 0.69097222 | AA56: 0.75416667 | AD56: 0.80972222 | AF56: 0.86527778
B57: OAKMOOR | C57: 0.19513889 | G57: 0.29652778 | L57: 0.40763889 | Q57: 0.51180556 | Y57: 0.66111111 | AC57: 0.76527778
B58: OLIFANTSFONTEIN | C58: 0.20069444 | G58: 0.30208333 | L58: 0.41319444 | Q58: 0.51736111 | Y58: 0.66666667 | AC58: 0.77083333
B59: PINEDENE
...

Sheet Archive_2025
A3: PTA-to-PIEN_Weekday
A6: STATION | B6: =UPPER("Coordinates") -> COORDINATES | C6: 9181 | D6: 1151 | E6: 9183 | F6: 1152 | G6: 1105 | H6: 1155 | I6: 1107 | J6: 1154 | K6: 1129 | L6: 1159 | M6: 1111 | N6: 1161 | O6: 1112 | P6: 1162 | Q6: 1115 | R6: 9129 | S6: 9111 | T6: 9152 | U6: 9115 | V6: 9117 | W6: 9119 | X6: 1167 | Y6: 1122 | Z6: 1165 | AA6: 1121 | AB6: 1171 | AC6: 1127 | AD6: 1169 | AE6: 1125 | AF6: 1172 | AG6: 1129 | AH6: 9121 | AI6: 9123 | AM6: Inter-station times
A7: PRETORIA | B7: -25.75864361043285, 28.189866445989118 | D7: 0.1875 | F7: 0.21527778 | H7: 0.22222222 | J7: 0.26527778 | L7: 0.27916667 | N7: =M19 -> #REF! | P7: 0.33680556 | R7: 0.36111111 | S7: 0.4375 | T7: 0.51388889 | U7: 0.59027778 | V7: 0.62847222 | W7: 0.63541667 | X7: 0.66319444 | Z7: 0.67013889 | AB7: 0.70486111 | AD7: =AB14 -> #REF! | AF7: 0.75 | AH7: =AH8-#REF! -> #REF! | AI7: =AI8-#REF! -> #REF! | AM7: 40min TRIP | AN7: 45min TRIP
A8: MEARS STREET | B8: -25.759836388884576, 28.201559350093763 | D8: 0.18958333 | F8: =F7+#REF!+TIME(0,1,0) -> #REF! | H8: =H7+#REF! -> #REF! | J8: =J7+#REF! -> #REF! | L8: 0.28055556 | N8: =N7+#REF!+TIME(0,1,0) -> #REF! | P8: 0.33888889 | R8: =R7+#REF! -> #REF! | S8: =S7+#REF! -> #REF! | T8: =T7+#REF! -> #REF! | U8: =U7+#REF! -> #REF! | V8: =V7+#REF! -> #REF! | W8: =W7+#REF! -> #REF! | X8: =X7+#REF! -> #REF! | Z8: =Z7+#REF! -> #REF! | AB8: =AB7+#REF! -> #REF! | AD8: =AD7+#REF!+TIME(0,1,0) -> #REF! | AF8: =AF7+#REF!+TIME(0,1,0) -> #REF! | AH8: 0.76388889 | AI8: 0.80902778 | AL8: ='PTA-to-PIEN_Weekday'!A3 -> PRETORIA | AM8: 0 | AN8: 0
A9: DEVENISH STREET | B9: -25.760571651064055, 28.209966455924803 | D9: 0.19097222 | F9: =F8+#REF! -> #REF! | H9: =H8+#REF! -> #REF! | J9: =J8+#REF! -> #REF! | L9: 0.28194444 | N9: =N8+#REF! -> #REF! | P9: 0.34027778 | R9: =R8+#REF! -> #REF! | S9: =S8+#REF! -> #REF! | T9: =T8+#REF! -> #REF! | U9: =U8+#REF! -> #REF! | V9: =V8+#REF! -> #REF! | W9: =W8+#REF! -> #REF! | X9: =X8+#REF! -> #REF! | Z9: =Z8+#REF! -> #REF! | AB9: =AB8+#REF! -> #REF! | AD9: =AD8+#REF! -> #REF! | AF9: =AF8+#REF! -> #REF! | AH9: =AH8+#REF! -> #REF! | AI9: =AI8+#REF! -> #REF! | AL9: ='PTA-to-PIEN_Weekday'!A4 -> MEARS STREET | AM9: 0.0020833333 | AN9: 0.0020833333
A10: WALKER STREET | B10: -25.76012800529803, 28.213499980098053 | D10: 0.19236111 | F10: =F9+#REF! -> #REF! | H10: =H9+#REF! -> #REF! | J10: =J9+#REF! -> #REF! | L10: 0.28333333 | N10: =N9+#REF! -> #REF! | P10: 0.34166667 | R10: =R9+#REF! -> #REF! | S10: =S9+#REF! -> #REF! | T10: =T9+#REF! -> #REF! | U10: =U9+#REF! -> #REF! | V10: =V9+#REF! -> #REF! | W10: =W9+#REF! -> #REF! | X10: =X9+#REF! -> #REF! | Z10: =Z9+#REF! -> #REF! | AB10: =AB9+#REF! -> #REF! | AD10: =AD9+#REF! -> #REF! | AF10: =AF9+#REF! -> #REF! | AH10: =AH9+#REF!+TIME(0,1,0) -> #REF! | AI10: =AI9+#REF! -> #REF! | AL10: ='PTA-to-PIEN_Weekday'!A5 -> DEVENISH STREET | AM10: 0.0013888889 | AN10: 0.0013888889
A11: LOFTUS VERSFELD PARK | B11: -25.754940155678536, 28.22535667426071 | D11: 0.19444444 | F11: =F10+#REF! -> #REF! | H11: =H10+#REF! -> #REF! | J11: =J10+#REF! -> #REF! | L11: 0.28541667 | N11: =N10+#REF! -> #REF! | P11: 0.34375 | R11: =R10+#REF! -> #REF! | S11: =S10+#REF! -> #REF! | T11: =T10+#REF! -> #REF! | U11: =U10+#REF! -> #REF! | V11: =V10+#REF! -> #REF! | W11: =W10+#REF! -> #REF! | X11: =X10+#REF! -> #REF! | Z11: =Z10+#REF! -> #REF! | AB11: =AB10+#REF! -> #REF! | AD11: =AD10+#REF! -> #REF! | AF11: =AF10+#REF!-TIME(0,1,0) -> #REF! | AH11: =AH10+#REF!-TIME(0,1,0) -> #REF! | AI11: =AI10+#REF! -> #REF! | AL11: ='PTA-to-PIEN_Weekday'!A6 -> WALKER STREET | AM11: 0.0013888889 | AN11: 0.0013888889
A12: RISSIK | B12: -25.749263370927064, 28.232274866782785 | D12: 0.19583333 | F12: =F11+#REF! -> #REF! | H12: =H11+#REF! -> #REF! | J12: =J11+#REF! -> #REF! | L12: 0.28680556 | N12: =N11+#REF! -> #REF! | P12: 0.34583333 | R12: =R11+#REF! -> #REF! | S12: =S11+#REF! -> #REF! | T12: =T11+#REF! -> #REF! | U12: =U11+#REF! -> #REF! | V12: =V11+#REF! -> #REF! | W12: =W11+#REF! -> #REF! | X12: =X11+#REF! -> #REF! | Z12: =Z11+#REF! -> #REF! | AB12: =AB11+#REF! -> #REF! | AD12: =AD11+#REF! -> #REF! | AF12: =AF11+#REF!+TIME(0,1,0) -> #REF! | AH12: =AH11+#REF!+TIME(0,1,0) -> #REF! | AI12: =AI11+#REF!+TIME(0,1,0) -> #REF! | AL12: ='PTA-to-PIEN_Weekday'!A7 -> LOFTUS VERSFELD PARK | AM12: 0.0020833333 | AN12: 0.0020833333
A13: HARTBEESSPRUIT | B13: -25.746516360305577, 28.2411523995095 | D13: 0.19791667 | F13: =F12+#REF! -> #REF! | H13: =H12+#REF! -> #REF! | J13: =J12+#REF! -> #REF! | L13: 0.28819444 | N13: =N12+#REF! -> #REF! | P13: 0.34722222 | R13: =R12+#REF!-TIME(0,1,0) -> #REF! | S13: =S12+#REF! -> #REF! | T13: =T12+#REF! -> #REF! | U13: =U12+#REF! -> #REF! | V13: =V12+#REF! -> #REF! | W13: =W12+#REF! -> #REF! | X13: =X12+#REF! -> #REF! | Z13: =Z12+#REF! -> #REF! | AB13: =AB12+#REF! -> #REF! | AD13: =AD12+#REF! -> #REF! | AF13: =AF12+#REF! -> #REF! | AH13: =AH12+#REF! -> #REF! | AI13: =AI12+#REF!+TIME(0,1,0) -> #REF! | AL13: ='PTA-to-PIEN_Weekday'!A8 -> RISSIK | AM13: 0.0013888889 | AN13: 0.0013888889
A14: KOEDOESPOORT | B14: -25.72608149772232, 28.27872645216183 | C14: 0.19097222 | D14: 0.20138889 | E14: 0.21180556 | F14: =F13+#REF!+TIME(0,1,0) -> #REF! | G14: 0.23958333 | H14: =H13+#REF! -> #REF! | I14: 0.25 | J14: =J13+#REF! -> #REF! | K14: 0.28819444 | L14: 0.29166667 | M14: 0.30208333 | N14: =N13+#REF! -> #REF! | O14: 0.33680556 | P14: 0.35069444 | Q14: 0.35763889 | R14: =R13+#REF!+TIME(0,1,0) -> #REF! | S14: =S13+#REF! -> #REF! | T14: =T13+#REF! -> #REF! | U14: =U13+#REF! -> #REF! | V14: =V13+#REF! -> #REF! | W14: =W13+#REF! -> #REF! | X14: =X13+#REF!+TIME(0,2,0) -> #REF! | Y14: =Z14 -> #REF! | Z14: =Z13+#REF!+TIME(0,2,0) -> #REF! | AA14: 0.69097222 | AB14: =AB13+#REF!+TIME(0,1,0)+TIME(0,1,0) -> #REF! | AC14: 0.72569444 | AD14: =AD13+#REF! -> #REF! | AE14: 0.73958333 | AF14: =AF13+#REF! -> #REF! | AG14: 0.77083333 | AH14: =AH13+#REF! -> #REF! | AI14: =AI13+#REF!+TIME(0,1,0)+TIME(0,1,0) -> #REF! | AL14: ='PTA-to-PIEN_Weekday'!A9 -> HARTBEESSPRUIT | AM14: 0.0020833333 | AN14: 0.0013888889
A15: SILVERTON | B15: -25.727434500448368, 28.296925669958974 | C15: 0.19236111 | E15: =E14+#REF!-TIME(0,1,0) -> #REF! | G15: =G14+#REF! -> #REF! | I15: 0.25277778 | K15: 0.29027778 | M15: =M14+#REF! -> #REF! | O15: 0.33819444 | Q15: =Q14+#REF!-TIME(0,1,0) -> #REF! | R15: =R14+#REF! -> #REF! | S15: =S14+#REF! -> #REF! | T15: =T14+#REF! -> #REF! | U15: =U14+#REF! -> #REF! | V15: =V14+#REF! -> #REF! | W15: =W14+#REF! -> #REF! | Y15: =Y14+#REF!-TIME(0,2,0) -> #REF! | AA15: =AA14+#REF!-TIME(0,2,0) -> #REF! | AC15: =AC14+#REF! -> #REF! | AE15: =AE14+#REF! -> #REF! | AG15: =AG14+#REF!-TIME(0,1,0) -> #REF! | AH15: =AH14+#REF! -> #REF! | AI15: =AI14+#REF!-TIME(0,1,0) -> #REF! | AL15: ='PTA-to-PIEN_Weekday'!A11 -> KOEDOESPOORT | AM15: 0.0020833333 | AN15: 0.0034722222
A16: WALTOO | B16: -25.716968225345873, 28.321353261409016 | C16: 0.19513889 | E16: =E15+#REF!+TIME(0,1,0) -> #REF! | G16: =G15+#REF! -> #REF! | I16: 0.25486111 | K16: 0.29236111 | M16: =M15+#REF! -> #REF! | O16: 0.34097222 | Q16: =Q15+#REF! -> #REF! | R16: =R15+#REF! -> #REF! | S16: =S15+#REF! -> #REF! | T16: =T15+#REF! -> #REF! | U16: =U15+#REF! -> #REF! | V16: =V15+#REF! -> #REF! | W16: =W15+#REF! -> #REF! | Y16: =Y15+#REF!+TIME(0,1,0) -> #REF! | AA16: =AA15+#REF!+TIME(0,1,0) -> #REF! | AC16: =AC15+#REF! -> #REF! | AE16: =AE15+#REF! -> #REF! | AG16: =AG15+#REF!+TIME(0,1,0) -> #REF! | AH16: =AH15+#REF! -> #REF! | AI16: =AI15+#REF! -> #REF! | AL16: ='PTA-to-PIEN_Weekday'!A12 -> SILVERTON | AM16: 0.0027777778 | AN16: 0.0020833333
A17: DENNEBOOM | B17: -25.719077472725353, 28.336637070658863 | C17: 0.19652778 | E17: =E16+#REF!-TIME(0,1,0) -> #REF! | G17: =G16+#REF!-TIME(0,1,0) -> #REF! | I17: 0.25625 | K17: 0.29375 | M17: =M16+#REF!-TIME(0,1,0) -> #REF! | O17: 0.34236111 | Q17: =Q16+#REF! -> #REF! | R17: =R16+#REF! -> #REF! | S17: =S16+#REF! -> #REF! | T17: =T16+#REF! -> #REF! | U17: =U16+#REF! -> #REF! | V17: =V16+#REF! -> #REF! | W17: =W16+#REF! -> #REF! | Y17: =Y16+#REF! -> #REF! | AA17: =AA16+#REF! -> #REF! | AC17: =AC16+#REF!-TIME(0,1,0) -> #REF! | AE17: =AE16+#REF!-TIME(0,1,0) -> #REF! | AG17: =AG16+#REF!-TIME(0,1,0) -> #REF! | AH17: =AH16+#REF! -> #REF! | AI17: =AI16+#REF! -> #REF! | AL17: ='PTA-to-PIEN_Weekday'!A14 -> WALTOO | AM17: 0.0020833333 | AN17: 0.0020833333
A18: EERSTE FABRIEKE | B18: -25.7221815801619, 28.359894081240192 | C18: 0.19861111 | E18: =E17+#REF!+TIME(0,1,0) -> #REF! | G18: =G17+#REF! -> #REF! | I18: 0.25833333 | K18: 0.29583333 | M18: =M17+#REF! -> #REF! | O18: 0.34444444 | Q18: =Q17+#REF! -> #REF! | R18: =R17+#REF! -> #REF! | S18: =S17+#REF! -> #REF! | T18: =T17+#REF! -> #REF! | U18: =U17+#REF! -> #REF! | V18: =V17+#REF! -> #REF! | W18: =W17+#REF! -> #REF! | Y18: =Y17+#REF!+TIME(0,1,0) -> #REF! | AA18: =AA17+#REF! -> #REF! | AC18: =AC17+#REF!+TIME(0,1,0) -> #REF! | AE18: =AE17+#REF! -> #REF! | AG18: =AG17+#REF!+TIME(0,1,0) -> #REF! | AH18: =AH17+#REF! -> #REF! | AI18: =AI17+#REF!+TIME(0,1,0) -> #REF! | AL18: ='PTA-to-PIEN_Weekday'!A15 -> DENNEBOOM | AM18: 0.0013888889 | AN18: 0.0020833333
A19: MAMELODI GARDENS | B19: -25.727137148700365, 28.38522516947939 | C19: 0.20138889 | E19: =E18+#REF!-TIME(0,1,0) -> #REF! | G19: =G18+#REF! -> #REF! | I19: 0.26041667 | K19: 0.29861111 | M19: =M18+#REF! -> #REF! | O19: 0.34722222 | Q19: =Q18+#REF! -> #REF! | R19: =R18+#REF! -> #REF! | S19: =S18+#REF! -> #REF! | T19: =T18+#REF! -> #REF! | U19: =U18+#REF! -> #REF! | V19: =V18+#REF! -> #REF! | W19: =W18+#REF! -> #REF! | Y19: =Y18+#REF! -> #REF! | AA19: =AA18+#REF!-TIME(0,1,0) -> #REF! | AC19: =AC18+#REF!-TIME(0,1,0) -> #REF! | AE19: =AE18+#REF! -> #REF! | AG19: =AG18+#REF!-TIME(0,1,0) -> #REF! | AH19: =AH18+#REF! -> #REF! | AI19: =AI18+#REF!-TIME(0,1,0) -> #REF! | AL19: ='PTA-to-PIEN_Weekday'!A16 -> EERSTE FABRIEKE | AM19: 0.0020833333 | AN19: 0.0020833333
A20: PIENAARSPOORT | B20: -25.734672061252613, 28.426968817228143 | C20: 0.20833333 | G20: =G19+#REF! -> #REF! | K20: 0.30555556 | O20: 0.35416667 | R20: =R19+#REF!+TIME(0,5,0) -> #REF! | S20: =S19+#REF!+TIME(0,5,0) -> #REF! | T20: =T19+#REF!+TIME(0,5,0) -> #REF! | U20: =U19+#REF!+TIME(0,5,0) -> #REF! | V20: =V19+#REF!+TIME(0,5,0) -> #REF! | AA20: =AA19+#REF!+TIME(0,5,0) -> #REF! | AE20: =AE19+#REF! -> #REF! | AH20: =AH19+#REF! -> #REF! | AI20: =AI19+#REF!+TIME(0,5,0) -> #REF! | AL20: ='PTA-to-PIEN_Weekday'!A17 -> MAMELODI GARDENS | AM20: 0.0034722222 | AN20: 0.0027777778
AL21: ='PTA-to-PIEN_Weekday'!A19 -> PIENAARSPOORT | AM21: 0.0034722222 | AN21: 0.0069444444
AM22: 9 | AN22: 9
A23: PIEN - PTA (Weekday)
A26: STATION | B26: COORDINATES | C26: 1100 | D26: 1150 | E26: 1102 | F26: 1152 | G26: 1134 | H26: 1154 | I26: 1106 | J26: 1156 | K26: 1106 | L26: 1158 | M26: 1110 | N26: 1163 | O26: 1112 | P26: 1162 | Q26: 1114 | R26: 1154 | S26: 9108 | T26: 9106 | U26: 9110 | V26: 9112 | W26: 9154 | X26: 9116 | Y26: 1122 | Z26: 1120 | AA26: 1168 | AB26: 1166 | AC26: 1125 | AD26: 1124 | AE26: 1172 | AF26: 1170 | AG26: 1128 | AH26: 9122 | AI26: 1174 | AM26: Cummulative times | AN26: Inter-station times
A27: PIENAARSPOORT | B27: -25.734672061252613, 28.426968817228143 | C27: 0.16666667 | G27: 0.21527778 | K27: =J40 -> #REF! | O27: 0.3125 | S27: 0.36111111 | U27: =T40 -> #REF! | V27: =U40+TIME(1,5,0) -> #REF! | W27: 0.55208333 | X27: 0.62847222 | Z27: =Y28 -> 0.66666667 | AD27: 0.71527778 | AH27: =AG33 -> #REF! | AL27: ='PIEN-to-PTA_Weekday'!A3 -> PIENAARSPOORT | AM27: 0 | AN27: 0
A28: MAMELODI GARDENS | B28: -25.727137148700365, 28.38522516947939 | C28: =C27+#REF! -> #REF! | E28: 0.19097222 | G28: =G27+#REF! -> #REF! | I28: =G33 -> #REF! | K28: =K27+#REF! -> #REF! | M28: 0.26736111 | O28: =O27+#REF! -> #REF! | Q28: =O33 -> #REF! | S28: =S27+#REF! -> #REF! | T28: 0.375 | U28: =U27+#REF! -> #REF! | V28: =V27+#REF! -> #REF! | W28: =W27+#REF! -> #REF! | X28: =X27+#REF! -> #REF! | Y28: 0.66666667 | Z28: =Z27+#REF! -> #REF! | AC28: =AB40 -> #REF! | AD28: =AD27+#REF! -> #REF! | AG28: 0.75347222 | AH28: =AH27+#REF! -> #REF! | AL28: ='PIEN-to-PTA_Weekday'!A5 -> MAMELODI GARDENS | AM28: 0.00625 | AN28: 0.00625
A29: EERSTE FABRIEKE | B29: -25.7221815801619, 28.359894081240192 | C29: =C28+#REF! -> #REF! | E29: =E28+#REF!-TIME(0,1,0) -> #REF! | G29: =G28+#REF! -> #REF! | I29: =I28+#REF!-TIME(0,1,0) -> #REF! | K29: =K28+#REF! -> #REF! | M29: 0.27013889 | O29: =O28+#REF! -> #REF! | Q29: =Q28+#REF!-TIME(0,1,0) -> #REF! | S29: =S28+#REF! -> #REF! | T29: =T28+#REF!-TIME(0,1,0) -> #REF! | U29: =U28+#REF! -> #REF! | V29: =V28+#REF! -> #REF! | W29: =W28+#REF! -> #REF! | X29: =X28+#REF! -> #REF! | Y29: =Y28+#REF!-TIME(0,1,0) -> #REF! | Z29: =Z28+#REF! -> #REF! | AC29: =AC28+#REF!-TIME(0,1,0) -> #REF! | AD29: =AD28+#REF! -> #REF! | AG29: =AG28+#REF!-TIME(0,1,0) -> #REF! | AH29: =AH28+#REF! -> #REF! | AL29: ='PIEN-to-PTA_Weekday'!A6 -> EERSTE FABRIEKE | AM29: 0.0097222222 | AN29: 0.0034722222
A30: DENNEBOOM | B30: -25.719077472725353, 28.336637070658863 | C30: =C29+#REF! -> #REF! | E30: =E29+#REF! -> #REF! | G30: =G29+#REF! -> #REF! | I30: =I29+#REF! -> #REF! | K30: =K29+#REF! -> #REF! | M30: 0.27222222 | O30: =O29+#REF! -> #REF! | Q30: =Q29+#REF! -> #REF! | S30: =S29+#REF! -> #REF! | T30: =T29+#REF! -> #REF! | U30: =U29+#REF! -> #REF! | V30: =V29+#REF! -> #REF! | W30: =W29+#REF! -> #REF! | X30: =X29+#REF! -> #REF! | Y30: =Y29+#REF! -> #REF! | Z30: =Z29+#REF! -> #REF! | AC30: =AC29+#REF! -> #REF! | AD30: =AD29+#REF! -> #REF! | AG30: =AG29+#REF! -> #REF! | AH30: =AH29+#REF! -> #REF! | AL30: ='PIEN-to-PTA_Weekday'!A7 -> DENNEBOOM | AM30: 0.011805556 | AN30: 0.0020833333
A31: WALTOO | B31: -25.716968225345873, 28.321353261409016 | C31: =C30+#REF! -> #REF! | E31: =E30+#REF! -> #REF! | G31: =G30+#REF! -> #REF! | I31: =I30+#REF! -> #REF! | K31: =K30+#REF! -> #REF! | M31: 0.27361111 | O31: =O30+#REF! -> #REF! | Q31: =Q30+#REF! -> #REF! | S31: =S30+#REF! -> #REF! | T31: =T30+#REF! -> #REF! | U31: =U30+#REF! -> #REF! | V31: =V30+#REF! -> #REF! | W31: =W30+#REF! -> #REF! | X31: =X30+#REF! -> #REF! | Y31: =Y30+#REF! -> #REF! | Z31: =Z30+#REF! -> #REF! | AC31: =AC30+#REF! -> #REF! | AD31: =AD30+#REF! -> #REF! | AG31: =AG30+#REF! -> #REF! | AH31: =AH30+#REF! -> #REF! | AL31: ='PIEN-to-PTA_Weekday'!A8 -> WALTOO | AM31: 0.013194444 | AN31: 0.0013888889
A32: SILVERTON | B32: -25.727434500448368, 28.296925669958974 | C32: =C31+#REF! -> #REF! | E32: =E31+#REF! -> #REF! | G32: =G31+#REF! -> #REF! | I32: =I31+#REF! -> #REF! | K32: =K31+#REF! -> #REF! | M32: 0.27569444 | O32: =O31+#REF! -> #REF! | Q32: =Q31+#REF! -> #REF! | S32: =S31+#REF! -> #REF! | T32: =T31+#REF! -> #REF! | U32: =U31+#REF! -> #REF! | V32: =V31+#REF! -> #REF! | W32: =W31+#REF! -> #REF! | X32: =X31+#REF! -> #REF! | Y32: =Y31+#REF! -> #REF! | Z32: =Z31+#REF! -> #REF! | AC32: =AC31+#REF! -> #REF! | AD32: =AD31+#REF! -> #REF! | AG32: =AG31+#REF! -> #REF! | AH32: =AH31+#REF! -> #REF! | AL32: ='PIEN-to-PTA_Weekday'!A10 -> SILVERTON | AM32: 0.015277778 | AN32: 0.0020833333
A33: KOEDOESPOORT | B33: -25.72608149772232, 28.27872645216183 | C33: =C32+#REF! -> #REF! | D33: =C33+TIME(0,10,0) -> #REF! | E33: =E32+#REF! -> #REF! | F33: 0.20833333 | G33: =G32+#REF! -> #REF! | H33: =I31+TIME(0,1,0) -> #REF! | I33: =I32+#REF! -> #REF! | J33: 0.25 | K33: =K32+#REF! -> #REF! | L33: 0.28819444 | M33: 0.27777778 | N33: 0.29861111 | O33: =O32+#REF! -> #REF! | P33: 0.33680556 | Q33: =Q32+#REF! -> #REF! | R33: =P40+TIME(0,10,0) -> #REF! | S33: =S32+#REF! -> #REF! | T33: =T32+#REF! -> #REF! | U33: =U32+#REF! -> #REF! | V33: =V32+#REF! -> #REF! | W33: =W32+#REF! -> #REF! | X33: =X32+#REF! -> #REF! | Y33: =Y32+#REF! -> #REF! | Z33: =Z32+#REF! -> #REF! | AA33: =Z33 -> #REF! | AB33: =AA38 -> #REF! | AC33: =AC32+#REF! -> #REF! | AD33: =AD32+#REF! -> #REF! | AE33: =AD33-TIME(0,10,0) -> #REF! | AF33: 0.74305556 | AG33: =AG32+#REF! -> #REF! | AH33: =AH32+#REF! -> #REF! | AI33: =AH27+TIME(0,10,0) -> #REF! | AL33: ='PIEN-to-PTA_Weekday'!A11 -> KOEDOESPOORT | AM33: 0.017361111 | AN33: 0.0020833333
A34: HARTBEESSPRUIT | B34: -25.746516360305577, 28.2411523995095 | D34: =D33+#REF! -> #REF! | F34: =F33+#REF! -> #REF! | H34: =H33+#REF! -> #REF! | J34: =J33+#REF! -> #REF! | L34: =L33+#REF! -> #REF! | N34: =N33+#REF! -> #REF! | P34: =P33+#REF! -> #REF! | R34: =R33+#REF! -> #REF! | S34: =S33+#REF! -> #REF! | T34: =T33+#REF! -> #REF! | U34: =U33+#REF! -> #REF! | V34: =V33+#REF! -> #REF! | W34: =W33+#REF! -> #REF! | X34: =X33+#REF! -> #REF! | AA34: =AA33+#REF! -> #REF! | AB34: =AB33+#REF! -> #REF! | AE34: =AE33+#REF! -> #REF! | AF34: =AF33+#REF! -> #REF! | AH34: =AH33+#REF! -> #REF! | AI34: =AI33+#REF! -> #REF! | AL34: ='PIEN-to-PTA_Weekday'!A13 -> HARTBEESSPRUIT | AM34: 0.019444444 | AN34: 0.0020833333
A35: RISSIK | B35: -25.749263370927064, 28.232274866782785 | D35: =D34+#REF! -> #REF! | F35: =F34+#REF! -> #REF! | H35: =H34+#REF! -> #REF! | J35: =J34+#REF! -> #REF! | L35: =L34+#REF! -> #REF! | N35: =N34+#REF! -> #REF! | P35: =P34+#REF! -> #REF! | R35: =R34+#REF! -> #REF! | S35: =S34+#REF! -> #REF! | T35: =T34+#REF! -> #REF! | U35: =U34+#REF! -> #REF! | V35: =V34+#REF! -> #REF! | W35: =W34+#REF! -> #REF! | X35: =X34+#REF! -> #REF! | AA35: =AA34+#REF! -> #REF! | AB35: =AB34+#REF! -> #REF! | AE35: =AE34+#REF! -> #REF! | AF35: =AF34+#REF! -> #REF! | AH35: =AH34+#REF! -> #REF! | AI35: =AI34+#REF! -> #REF! | AL35: ='PIEN-to-PTA_Weekday'!A14 -> RISSIK | AM35: 0.022916667 | AN35: 0.0027777778
A36: LOFTUS VERSFELD PARK | B36: -25.754940155678536, 28.22535667426071 | D36: =D35+#REF! -> #REF! | F36: =F35+#REF! -> #REF! | H36: =H35+#REF! -> #REF! | J36: =J35+#REF! -> #REF! | L36: =L35+#REF! -> #REF! | N36: =N35+#REF! -> #REF! | P36: =P35+#REF! -> #REF! | R36: =R35+#REF! -> #REF! | S36: =S35+#REF! -> #REF! | T36: =T35+#REF! -> #REF! | U36: =U35+#REF! -> #REF! | V36: =V35+#REF! -> #REF! | W36: =W35+#REF! -> #REF! | X36: =X35+#REF! -> #REF! | AA36: =AA35+#REF! -> #REF! | AB36: =AB35+#REF! -> #REF! | AE36: =AE35+#REF! -> #REF! | AF36: =AF35+#REF! -> #REF! | AH36: =AH35+#REF! -> #REF! | AI36: =AI35+#REF! -> #REF! | AL36: ='PIEN-to-PTA_Weekday'!A15 -> LOFTUS VERSFELD PARK | AM36: 0.024305556 | AN36: 0.0020833333
A37: WALKER STREET | B37: -25.76012800529803, 28.213499980098053 | D37: =D36+#REF! -> #REF! | F37: =F36+#REF! -> #REF! | H37: =H36+#REF! -> #REF! | J37: =J36+#REF! -> #REF! | L37: =L36+#REF! -> #REF! | N37: =N36+#REF! -> #REF! | P37: =P36+#REF! -> #REF! | R37: =R36+#REF! -> #REF! | S37: =S36+#REF! -> #REF! | T37: =T36+#REF! -> #REF! | U37: =U36+#REF! -> #REF! | V37: =V36+#REF! -> #REF! | W37: =W36+#REF! -> #REF! | X37: =X36+#REF! -> #REF! | AA37: =AA36+#REF! -> #REF! | AB37: =AB36+#REF! -> #REF! | AE37: =AE36+#REF! -> #REF! | AF37: =AF36+#REF! -> #REF! | AH37: =AH36+#REF! -> #REF! | AI37: =AI36+#REF! -> #REF! | AL37: ='PIEN-to-PTA_Weekday'!A16 -> WALKER STREET | AM37: 0.026388889 | AN37: 0.0020833333
A38: DEVENISH STREET | B38: -25.760571651064055, 28.209966455924803 | D38: =D37+#REF! -> #REF! | F38: =F37+#REF! -> #REF! | H38: =H37+#REF! -> #REF! | J38: =J37+#REF! -> #REF! | L38: =L37+#REF! -> #REF! | N38: =N37+#REF! -> #REF! | P38: =P37+#REF! -> #REF! | R38: =R37+#REF! -> #REF! | S38: =S37+#REF! -> #REF! | T38: =T37+#REF! -> #REF! | U38: =U37+#REF! -> #REF! | V38: =V37+#REF! -> #REF! | W38: =W37+#REF! -> #REF! | X38: =X37+#REF! -> #REF! | AA38: =AA37+#REF! -> #REF! | AB38: =AB37+#REF! -> #REF! | AE38: =AE37+#REF! -> #REF! | AF38: =AF37+#REF! -> #REF! | AH38: =AH37+#REF! -> #REF! | AI38: =AI37+#REF! -> #REF! | AL38: ='PIEN-to-PTA_Weekday'!A17 -> DEVENISH STREET | AM38: 0.027777778 | AN38: 0.0013888889
A39: MEARS STREET | B39: -25.759836388884576, 28.201559350093763 | D39: =D38+#REF! -> #REF! | F39: =F38+#REF! -> #REF! | H39: =H38+#REF! -> #REF! | J39: =J38+#REF! -> #REF! | L39: =L38+#REF! -> #REF! | N39: =N38+#REF! -> #REF! | P39: =P38+#REF! -> #REF! | R39: =R38+#REF! -> #REF! | S39: =S38+#REF! -> #REF! | T39: =T38+#REF! -> #REF! | U39: =U38+#REF! -> #REF! | V39: =V38+#REF! -> #REF! | W39: =W38+#REF! -> #REF! | X39: =X38+#REF! -> #REF! | AA39: =AA38+#REF! -> #REF! | AB39: =AB38+#REF! -> #REF! | AE39: =AE38+#REF! -> #REF! | AF39: =AF38+#REF! -> #REF! | AH39: =AH38+#REF! -> #REF! | AI39: =AI38+#REF! -> #REF! | AL39: ='PIEN-to-PTA_Weekday'!A18 -> MEARS STREET | AM39: 0.028472222 | AN39: 0.00069444444
A40: PRETORIA | B40: -25.75864361043285, 28.189866445989118 | D40: =D39+#REF! -> #REF! | F40: =F39+#REF! -> #REF! | H40: =H39+#REF! -> #REF! | J40: =J39+#REF! -> #REF! | L40: =L39+#REF! -> #REF! | N40: =N39+#REF! -> #REF! | P40: =P39+#REF! -> #REF! | R40: =R39+#REF! -> #REF! | S40: =S39+#REF! -> #REF! | T40: =T39+#REF! -> #REF! | U40: =U39+#REF! -> #REF! | V40: =V39+#REF! -> #REF! | W40: =W39+#REF! -> #REF! | X40: =X39+#REF! -> #REF! | AA40: =AA39+#REF! -> #REF! | AB40: =AB39+#REF! -> #REF! | AE40: =AE39+#REF! -> #REF! | AF40: =AF39+#REF! -> #REF! | AH40: =AH39+#REF! -> #REF! | AI40: =AI39+#REF! -> #REF! | AL40: ='PIEN-to-PTA_Weekday'!A19 -> PRETORIA | AM40: 0.03125 | AN40: 0.0027777778
AM41: 9 | AN41: 9
A44: PTA-to-DEWIL_Weekday
A46: Last Updated: | B46: 45995 | C46: Z1
A47: STATION | B47: COORDINATES | C47: 4401 | D47: 4403 | E47: 4405 | F47: 4407 | G47: 4409 | H47: 4411 | I47: 4415 | J47: 4417 | K47: 4419 | L47: 4421 | M47: 4423 | N47: 4425 | O47: 4427 | P47: 4429 | Q47: 4431 | R47: 4433 | S47: 4435 | T47: 4437 | U47: 4439
A48: PRETORIA | B48: -25.75864361043285, 28.189866445989118 | C48: 0.21666667 | D48: 0.23611111 | E48: 0.26388889 | F48: 0.29166667 | G48: 0.32291667 | H48: 0.35069444 | I48: 0.40277778 | J48: 0.44791667 | K48: 0.5 | L48: 0.54513889 | M48: 0.59722222 | N48: 0.625 | O48: 0.64583333 | P48: 0.67013889 | Q48: 0.70347222 | R48: 0.72569444 | S48: 0.75694444 | T48: 0.78472222 | U48: 0.8125
A49: PRETORIA WES | B49: -25.75612607001734, 28.167454033423436 | C49: 0.22083333 | D49: 0.24027778 | E49: 0.26805556 | F49: 0.29583333 | G49: 0.32708333 | H49: 0.35486111 | I49: 0.40694444 | J49: 0.45208333 | K49: 0.50416667 | L49: 0.54930556 | M49: 0.60138889 | N49: 0.62916667 | O49: 0.65 | P49: 0.67430556 | Q49: 0.70763889 | R49: 0.72986111 | S49: 0.76111111 | T49: 0.78888889 | U49: 0.81666667
...

Sheet Config_GridOrder
A1: Key,SheetName,RowNumber,StartCol
A2: pta_to_pien_weekday,PTA-to-PIEN_Weekday,2,C
A3: pien_to_pta_weekday,PIEN-to-PTA_Weekday,2,C
A4: pta_to_pien_sat,PTA-to-PIEN_Sat,2,C
A5: pien_to_pta_sat,PIEN-to-PTA_Sat,2,C
A6: pta_to_pien_sun,PTA-to-PIEN_Sun,2,C
A7: pien_to_pta_sun,PIEN-to-PTA_Sun,2,C
A8: pta_to_dewil_weekday,PTA-to-DEWIL_Weekday,2,C
A9: dewil_to_pta_weekday,DEWIL-to-PTA_Weekday,2,C
A10: pta_to_dewil_sat,PTA-to-DEWIL_Sat,2,C
A11: dewil_to_pta_sat,DEWIL-to-PTA_Sat,2,C
A12: pta_to_dewil_sun,PTA-to-DEWIL_Sun,2,C
... A61: jhb_to_germ_sat,JHB-to-GERM_Sat,2,C

Sheet PTA-to-PIEN_Weekday
A1: Last Updated: | B1: 45890 | C1: Z2
A2: STATION | B2: =UPPER("Coordinates") -> COORDINATES | C2: 1101 | D2: 1151 | E2: 1103 | F2: 1153 | G2: 1105 | H2: 1155 | I2: 1107 | J2: 1157 | K2: 1109 | L2: 1159 | M2: 1111 | N2: 1161 | O2: 1113 | P2: 1163 | Q2: 1115 | R2: 9109 | S2: 9111 | T2: 9113 | U2: 9115 | V2: 9117 | W2: 9119 | X2: 1167 | Y2: 1123 | Z2: 1165 | AA2: 1121 | AB2: 1171 | AC2: 1127 | AD2: 1169 | AE2: 1125 | AF2: 1173 | AG2: 1129 | AH2: 9121 | AI2: 9123
A3: PRETORIA | B3: -25.75864361043285, 28.189866445989118 | D3: 0.1875 | F3: 0.21527778 | H3: 0.22916667 | J3: 0.26388889 | L3: 0.27777778 | N3: 0.3125 | P3: 0.33680556 | R3: 0.36111111 | S3: 0.4375 | T3: 0.51388889 | U3: 0.59027778 | V3: 0.62847222 | W3: 0.63541667 | X3: 0.66319444 | Z3: 0.67013889 | AB3: 0.70486111 | AD3: 0.71875 | AF3: 0.75 | AH3: 0.76388889 | AI3: 0.80902778
A4: MEARS STREET | B4: -25.759836388884576, 28.201559350093763 | D4: 0.19027778 | F4: 0.21805556 | H4: 0.23194444 | J4: 0.26666667 | L4: 0.28055556 | N4: 0.31527778 | P4: 0.33958333 | R4: 0.36319444 | S4: 0.43958333 | T4: 0.51597222 | U4: 0.59236111 | V4: 0.63055556 | W4: 0.63819444 | X4: 0.66597222 | Z4: 0.67291667 | AB4: 0.70763889 | AD4: 0.72152778 | AF4: 0.75277778 | AH4: 0.76597222 | AI4: 0.81111111
A5: DEVENISH STREET | B5: -25.760571651064055, 28.209966455924803 | D5: 0.19097222 | F5: 0.21875 | H5: 0.23263889 | J5: 0.26736111 | L5: 0.28125 | N5: 0.31597222 | P5: 0.34027778 | R5: 0.36458333 | S5: 0.44097222 | T5: 0.51736111 | U5: 0.59375 | V5: 0.63194444 | W5: 0.63888889 | X5: 0.66666667 | Z5: 0.67361111 | AB5: 0.70833333 | AD5: 0.72222222 | AF5: 0.75347222 | AH5: 0.76736111 | AI5: 0.8125
A6: WALKER STREET | B6: -25.76012800529803, 28.213499980098053 | D6: 0.19305556 | F6: 0.22083333 | H6: 0.23472222 | J6: 0.26944444 | L6: 0.28333333 | N6: 0.31805556 | P6: 0.34236111 | R6: 0.36597222 | S6: 0.44236111 | T6: 0.51875 | U6: 0.59513889 | V6: 0.63333333 | W6: 0.64027778 | X6: 0.66875 | Z6: 0.67569444 | AB6: 0.71041667 | AD6: 0.72430556 | AF6: 0.75555556 | AH6: 0.76875 | AI6: 0.81388889
A7: LOFTUS VERSFELD PARK | B7: -25.754940155678536, 28.22535667426071 | D7: 0.19444444 | F7: 0.22222222 | H7: 0.23611111 | J7: 0.27083333 | L7: 0.28472222 | N7: 0.31944444 | P7: 0.34375 | R7: 0.36805556 | S7: 0.44444444 | T7: 0.52083333 | U7: 0.59722222 | V7: 0.63541667 | W7: 0.64236111 | X7: 0.67013889 | Z7: 0.67708333 | AB7: 0.71180556 | AD7: 0.72569444 | AF7: 0.75694444 | AH7: 0.77083333 | AI7: 0.81597222
A8: RISSIK | B8: -25.749263370927064, 28.232274866782785 | D8: 0.19652778 | F8: 0.22430556 | H8: 0.23819444 | J8: 0.27291667 | L8: 0.28680556 | N8: 0.32152778 | P8: 0.34583333 | R8: 0.36944444 | S8: 0.44583333 | T8: 0.52222222 | U8: 0.59861111 | V8: 0.63680556 | W8: 0.64375 | X8: 0.67222222 | Z8: 0.67916667 | AB8: 0.71388889 | AD8: 0.72777778 | AF8: 0.75902778 | AH8: 0.77222222 | AI8: 0.81736111
A9: HARTBEESSPRUIT | B9: -25.746516360305577, 28.2411523995095 | D9: 0.19791667 | F9: 0.22569444 | H9: 0.23958333 | J9: 0.27430556 | L9: 0.28819444 | N9: 0.32291667 | P9: 0.34722222 | R9: 0.37083333 | S9: 0.44722222 | T9: 0.52361111 | U9: 0.6 | V9: 0.63819444 | W9: 0.64513889 | X9: 0.67361111 | Z9: 0.68055556 | AB9: 0.71527778 | AD9: 0.72916667 | AF9: 0.76041667 | AH9: 0.77361111 | AI9: 0.81875
A10: QUEENSWOOD | B10: -25.721853760563217, 28.25178790666072
A11: KOEDOESPOORT | B11: -25.72608149772232, 28.27872645216183 | C11: 0.19097222 | D11: 0.20138889 | E11: 0.21180556 | F11: 0.22916667 | G11: 0.23958333 | H11: 0.24305556 | I11: 0.25 | J11: 0.27777778 | K11: 0.28819444 | L11: 0.29166667 | M11: 0.30208333 | N11: 0.32638889 | O11: 0.33680556 | P11: 0.35069444 | Q11: 0.35763889 | R11: 0.37430556 | S11: 0.45069444 | T11: 0.52708333 | U11: 0.60347222 | V11: 0.64166667 | W11: 0.64861111 | X11: 0.67708333 | Y11: 0.68402778 | Z11: 0.68402778 | AA11: 0.69097222 | AB11: 0.71875 | AC11: 0.72569444 | AD11: 0.73263889 | AE11: 0.73958333 | AF11: 0.76388889 | AG11: 0.77083333 | AH11: 0.77708333 | AI11: 0.82222222
A12: SILVERTON | B12: -25.727388634278455, 28.29699912151972 | C12: 0.19236111 | E12: 0.21319444 | G12: 0.24097222 | I12: 0.25138889 | K12: 0.28958333 | M12: 0.30347222 | O12: 0.33819444 | Q12: 0.35902778 | R12: 0.37638889 | S12: 0.45277778 | T12: 0.52916667 | U12: 0.60555556 | V12: 0.64375 | W12: 0.65069444 | Y12: 0.68541667 | AA12: 0.69236111 | AC12: 0.72708333 | AE12: 0.74097222 | AG12: 0.77222222 | AH12: 0.77916667 | AI12: 0.82430556
A13: EERSTERUS | B13: -25.720262104484497, 28.30708446350365
A14: WALTOO | B14: -25.716964535181983, 28.32134413848142 | C14: 0.19513889 | E14: 0.21597222 | G14: 0.24375 | I14: 0.25416667 | K14: 0.29236111 | M14: 0.30625 | O14: 0.34097222 | Q14: 0.36180556 | R14: 0.37847222 | S14: 0.45486111 | T14: 0.53125 | U14: 0.60763889 | V14: 0.64583333 | W14: 0.65347222 | Y14: 0.68819444 | AA14: 0.69513889 | AC14: 0.72986111 | AE14: 0.74375 | AG14: 0.775 | AH14: 0.78125 | AI14: 0.82638889
A15: DENNEBOOM | B15: -25.719077472725353, 28.336637070658863 | C15: 0.19652778 | E15: 0.21736111 | G15: 0.24513889 | I15: 0.25555556 | K15: 0.29375 | M15: 0.30763889 | O15: 0.34236111 | Q15: 0.36319444 | R15: 0.38055556 | S15: 0.45694444 | T15: 0.53333333 | U15: 0.60972222 | V15: 0.64791667 | W15: 0.65486111 | Y15: 0.68958333 | AA15: 0.69652778 | AC15: 0.73125 | AE15: 0.74513889 | AG15: 0.77638889 | AH15: 0.78333333 | AI15: 0.82847222
A16: EERSTE FABRIEKE | B16: -25.7221815801619, 28.359894081240192 | C16: 0.19861111 | E16: 0.22013889 | G16: 0.24722222 | I16: 0.25833333 | K16: 0.29583333 | M16: 0.31041667 | O16: 0.34444444 | Q16: 0.36597222 | R16: 0.38263889 | S16: 0.45902778 | T16: 0.53541667 | U16: 0.61180556 | V16: 0.65 | W16: 0.65763889 | Y16: 0.69236111 | AA16: 0.69861111 | AC16: 0.73402778 | AE16: 0.74722222 | AG16: 0.77916667 | AH16: 0.78541667 | AI16: 0.83055556
A17: MAMELODI GARDENS | B17: -25.727137148700365, 28.38522516947939 | C17: 0.20138889 | E17: 0.22222222 | G17: 0.25 | I17: 0.26041667 | K17: 0.29861111 | M17: 0.3125 | O17: 0.34722222 | Q17: 0.36805556 | R17: 0.38541667 | S17: 0.46180556 | T17: 0.53819444 | U17: 0.61458333 | V17: 0.65277778 | W17: 0.65972222 | Y17: 0.69444444 | AA17: 0.70138889 | AC17: 0.73611111 | AE17: 0.75 | AG17: 0.78125 | AH17: 0.78819444 | AI17: 0.83333333
A18: GREENVIEW | B18: -25.73018814715231, 28.406238121914445
A19: PIENAARSPOORT | B19: -25.734672061252613, 28.426968817228143 | C19: 0.20833333 | G19: 0.25694444 | K19: 0.30555556 | O19: 0.35416667 | R19: 0.39236111 | S19: 0.46875 | T19: 0.54513889 | U19: 0.62152778 | V19: 0.65972222 | AA19: 0.70833333 | AE19: 0.75694444 | AH19: 0.79513889 | AI19: 0.84027778

Sheet PIEN-to-PTA_Weekday
A1: Last Updated: | B1: ='PTA-to-PIEN_Weekday'!B1 -> 45890 | C1: ='PTA-to-PIEN_Weekday'!C1 -> Z2
A2: STATION | B2: COORDINATES | C2: 1100 | D2: 1150 | E2: 1102 | F2: 1152 | G2: 1104 | H2: 1154 | I2: 1106 | J2: 1156 | K2: 1108 | L2: 1158 | M2: 1110 | N2: 1160 | O2: 1112 | P2: 1162 | Q2: 1114 | R2: 1164 | S2: 9108 | T2: 9106 | U2: 9110 | V2: 9112 | W2: 9114 | X2: 9116 | Y2: 1122 | Z2: 1168 | AA2: 1120 | AB2: 1166 | AC2: 1126 | AD2: 1172 | AE2: 1124 | AF2: 1170 | AG2: 1128 | AH2: 1174 | AI2: 9122
A3: PIENAARSPOORT | B3: -25.734672061252613, 28.426968817228143 | C3: 0.16666667 | G3: 0.21527778 | K3: 0.26388889 | O3: 0.3125 | S3: 0.36111111 | U3: 0.39930556 | V3: 0.47569444 | W3: 0.55208333 | X3: 0.62847222 | AA3: 0.66666667 | AE3: 0.71527778 | AI3: 0.76388889
A4: GREENVIEW | B4: -25.73018814715231, 28.406238121914445
A5: MAMELODI GARDENS | B5: -25.727137148700365, 28.38522516947939 | C5: 0.17291667 | E5: 0.19097222 | G5: 0.22152778 | I5: 0.23263889 | K5: 0.27013889 | M5: 0.26736111 | O5: 0.31875 | Q5: 0.32986111 | S5: 0.36736111 | T5: 0.375 | U5: 0.40555556 | V5: 0.48194444 | W5: 0.55833333 | X5: 0.63472222 | Y5: 0.66666667 | AA5: 0.67291667 | AC5: 0.70833333 | AE5: 0.72152778 | AG5: 0.75347222 | AI5: 0.77013889
A6: EERSTE FABRIEKE | B6: -25.7221815801619, 28.359894081240192 | C6: 0.17638889 | E6: 0.19375 | G6: 0.225 | I6: 0.23541667 | K6: 0.27361111 | M6: 0.27013889 | O6: 0.32222222 | Q6: 0.33263889 | S6: 0.37083333 | T6: 0.37777778 | U6: 0.40902778 | V6: 0.48541667 | W6: 0.56180556 | X6: 0.63819444 | Y6: 0.66944444 | AA6: 0.67638889 | AC6: 0.71111111 | AE6: 0.725 | AG6: 0.75625 | AI6: 0.77361111
A7: DENNEBOOM | B7: -25.719077472725353, 28.336637070658863 | C7: 0.17847222 | E7: 0.19583333 | G7: 0.22708333 | I7: 0.2375 | K7: 0.27569444 | M7: 0.27222222 | O7: 0.32430556 | Q7: 0.33472222 | S7: 0.37291667 | T7: 0.37986111 | U7: 0.41111111 | V7: 0.4875 | W7: 0.56388889 | X7: 0.64027778 | Y7: 0.67152778 | AA7: 0.67847222 | AC7: 0.71319444 | AE7: 0.72708333 | AG7: 0.75833333 | AI7: 0.77569444
A8: WALTOO | B8: -25.716950166393737, 28.32134413848142 | C8: 0.17986111 | E8: 0.19722222 | G8: 0.22847222 | I8: 0.23888889 | K8: 0.27708333 | M8: 0.27361111 | O8: 0.32569444 | Q8: 0.33611111 | S8: 0.37430556 | T8: 0.38125 | U8: 0.4125 | V8: 0.48888889 | W8: 0.56527778 | X8: 0.64166667 | Y8: 0.67291667 | AA8: 0.67986111 | AC8: 0.71458333 | AE8: 0.72847222 | AG8: 0.75972222 | AI8: 0.77708333
A9: EERSTERUS | B9: -25.720262104484497, 28.30708446350365
A10: SILVERTON | B10: -25.727388634278455, 28.29699912151972 | C10: 0.18194444 | E10: 0.19930556 | G10: 0.23055556 | I10: 0.24097222 | K10: 0.27916667 | M10: 0.27569444 | O10: 0.32777778 | Q10: 0.33819444 | S10: 0.37638889 | T10: 0.38402778 | U10: 0.41458333 | V10: 0.49097222 | W10: 0.56736111 | X10: 0.64375 | Y10: 0.675 | AA10: 0.68194444 | AC10: 0.71666667 | AE10: 0.73055556 | AG10: 0.76180556 | AI10: 0.77916667
A11: KOEDOESPOORT | B11: -25.72608149772232, 28.27872645216183 | C11: 0.18402778 | D11: 0.19097222 | E11: 0.20138889 | F11: 0.20833333 | G11: 0.23263889 | H11: 0.23958333 | I11: 0.24305556 | J11: 0.25 | K11: 0.28125 | L11: 0.28819444 | M11: 0.27777778 | N11: 0.29861111 | O11: 0.32986111 | P11: 0.33680556 | Q11: 0.34027778 | R11: 0.35763889 | S11: 0.37847222 | T11: 0.38541667 | U11: 0.41666667 | V11: 0.49305556 | W11: 0.56944444 | X11: 0.64583333 | Y11: 0.67708333 | Z11: 0.68402778 | AA11: 0.68402778 | AB11: 0.69444444 | AC11: 0.71875 | AD11: 0.72569444 | AE11: 0.73263889 | AF11: 0.74305556 | AG11: 0.76388889 | AH11: 0.77083333 | AI11: 0.78125
A12: QUEENSWOOD | B12: -25.721853760563217, 28.25178790666072
A13: HARTBEESSPRUIT | B13: -25.746516360305577, 28.2411523995095 | D13: 0.19444444 | F13: 0.21180556 | H13: 0.24305556 | J13: 0.25347222 | L13: 0.29166667 | N13: 0.30208333 | P13: 0.34027778 | R13: 0.36111111 | S13: 0.38263889 | T13: 0.38958333 | U13: 0.42083333 | V13: 0.49722222 | W13: 0.57361111 | X13: 0.65 | Z13: 0.6875 | AB13: 0.69791667 | AD13: 0.72916667 | AF13: 0.74652778 | AH13: 0.77430556 | AI13: 0.78541667
A14: RISSIK | B14: -25.749263370927064, 28.232274866782785 | D14: 0.19583333 | F14: 0.21319444 | H14: 0.24444444 | J14: 0.25486111 | L14: 0.29305556 | N14: 0.30347222 | P14: 0.34166667 | R14: 0.3625 | S14: 0.38402778 | T14: 0.39097222 | U14: 0.42222222 | V14: 0.49861111 | W14: 0.575 | X14: 0.65138889 | Z14: 0.68888889 | AB14: 0.69930556 | AD14: 0.73055556 | AF14: 0.74791667 | AH14: 0.77569444 | AI14: 0.78680556
A15: LOFTUS VERSFELD PARK | B15: -25.754940155678536, 28.22535667426071 | D15: 0.19791667 | F15: 0.21527778 | H15: 0.24652778 | J15: 0.25694444 | L15: 0.29513889 | N15: 0.30555556 | P15: 0.34375 | R15: 0.36458333 | S15: 0.38541667 | T15: 0.39236111 | U15: 0.42361111 | V15: 0.5 | W15: 0.57638889 | X15: 0.65277778 | Z15: 0.69097222 | AB15: 0.70138889 | AD15: 0.73263889 | AF15: 0.75 | AH15: 0.77777778 | AI15: 0.78819444
A16: WALKER STREET | B16: -25.76012800529803, 28.213499980098053 | D16: 0.2 | F16: 0.21736111 | H16: 0.24861111 | J16: 0.25902778 | L16: 0.29722222 | N16: 0.30763889 | P16: 0.34583333 | R16: 0.36666667 | S16: 0.3875 | T16: 0.39444444 | U16: 0.42569444 | V16: 0.50208333 | W16: 0.57847222 | X16: 0.65486111 | Z16: 0.69305556 | AB16: 0.70347222 | AD16: 0.73472222 | AF16: 0.75208333 | AH16: 0.77986111 | AI16: 0.79027778
A17: DEVENISH STREET | B17: -25.760571651064055, 28.209966455924803 | D17: 0.20069444 | F17: 0.21805556 | H17: 0.24930556 | J17: 0.25972222 | L17: 0.29791667 | N17: 0.30833333 | P17: 0.34652778 | R17: 0.36736111 | S17: 0.38888889 | T17: 0.39583333 | U17: 0.42708333 | V17: 0.50347222 | W17: 0.57986111 | X17: 0.65625 | Z17: 0.69375 | AB17: 0.70416667 | AD17: 0.73541667 | AF17: 0.75277778 | AH17: 0.78055556 | AI17: 0.79166667
A18: MEARS STREET | B18: -25.759836388884576, 28.201559350093763 | D18: 0.20208333 | F18: 0.21944444 | H18: 0.25069444 | J18: 0.26111111 | L18: 0.29930556 | N18: 0.30972222 | P18: 0.34791667 | R18: 0.36875 | S18: 0.38958333 | T18: 0.39652778 | U18: 0.42777778 | V18: 0.50416667 | W18: 0.58055556 | X18: 0.65694444 | Z18: 0.69513889 | AB18: 0.70555556 | AD18: 0.73680556 | AF18: 0.75416667 | AH18: 0.78194444 | AI18: 0.79236111
A19: PRETORIA | B19: -25.75864361043285, 28.189866445989118 | D19: 0.20486111 | F19: 0.22222222 | H19: 0.25347222 | J19: 0.26388889 | L19: 0.30208333 | N19: 0.3125 | P19: 0.35069444 | R19: 0.37152778 | S19: 0.39236111 | T19: 0.39930556 | U19: 0.43055556 | V19: 0.50694444 | W19: 0.58333333 | X19: 0.65972222 | Z19: 0.69791667 | AB19: 0.70833333 | AD19: 0.73958333 | AF19: 0.75694444 | AH19: 0.78472222 | AI19: 0.79513889
AP50: Cummulative times | AQ50: Inter-station times
AO51: =A3 -> PIENAARSPOORT | AP51: 0 | AQ51: 0
AO52: =A5 -> MAMELODI GARDENS | AP52: 0.00625 | AQ52: 0.00625
AO53: =A6 -> EERSTE FABRIEKE | AP53: 0.0097222222 | AQ53: 0.0034722222
AO54: =A7 -> DENNEBOOM | AP54: 0.011805556 | AQ54: 0.0020833333
AO55: =A8 -> WALTOO | AP55: 0.013194444 | AQ55: 0.0013888889
AO56: =A10 -> SILVERTON | AP56: 0.015277778 | AQ56: 0.0020833333
AO57: =A11 -> KOEDOESPOORT | AP57: 0.017361111 | AQ57: 0.0020833333
AO58: =A13 -> HARTBEESSPRUIT | AP58: 0.019444444 | AQ58: 0.0020833333
AO59: =A14 -> RISSIK | AP59: 0.022916667 | AQ59: 0.0027777778
AO60: =A15 -> LOFTUS VERSFELD PARK | AP60: 0.024305556 | AQ60: 0.0020833333
AO61: =A16 -> WALKER STREET | AP61: 0.026388889 | AQ61: 0.0020833333
AO62: =A17 -> DEVENISH STREET | AP62: 0.027777778 | AQ62: 0.0013888889
AO63: =A18 -> MEARS STREET | AP63: 0.028472222 | AQ63: 0.00069444444
AO64: =A19 -> PRETORIA | AP64: 0.03125 | AQ64: 0.0027777778
AP65: 9 | AQ65: 9

Sheet PTA-to-PIEN_Sat
A1: Last Updated: | B1: 45890 | C1: ='PTA-to-PIEN_Weekday'!C1 -> Z2
A2: STATION | B2: COORDINATES | C2: 9101 | D2: 9103 | E2: 9115 | F2: 9117 | G2: 9119
A3: PRETORIA | B3: -25.75864361043285, 28.189866445989118 | C3: 0.22291667 | D3: 0.29513889 | E3: 0.63194444 | F3: 0.70208333 | G3: 0.77916667
A4: MEARS STREET | B4: -25.759836388884576, 28.201559350093763 | C4: 0.225 | D4: 0.29722222 | E4: 0.63402778 | F4: 0.70416667 | G4: 0.78125
A5: DEVENISH STREET | B5: -25.760571651064055, 28.209966455924803 | C5: 0.22638889 | D5: 0.29861111 | E5: 0.63541667 | F5: 0.70555556 | G5: 0.78263889
A6: WALKER STREET | B6: -25.76012800529803, 28.213499980098053 | C6: 0.22708333 | D6: 0.29930556 | E6: 0.63611111 | F6: 0.70625 | G6: 0.78333333
A7: LOFTUS VERSFELD PARK | B7: -25.754940155678536, 28.22535667426071 | C7: 0.22916667 | D7: 0.30138889 | E7: 0.63819444 | F7: 0.70833333 | G7: 0.78541667
A8: RISSIK | B8: -25.749263370927064, 28.232274866782785 | C8: 0.23055556 | D8: 0.30277778 | E8: 0.63958333 | F8: 0.70972222 | G8: 0.78680556
A9: HARTBEESSPRUIT | B9: -25.746516360305577, 28.2411523995095 | C9: 0.23263889 | D9: 0.30486111 | E9: 0.64166667 | F9: 0.71180556 | G9: 0.78888889
A10: QUEENSWOOD | B10: -25.721853760563217, 28.25178790666072
A11: KOEDOESPOORT | B11: -25.72608149772232, 28.27872645216183 | C11: 0.23472222 | D11: 0.30694444 | E11: 0.64375 | F11: 0.71388889 | G11: 0.79097222
A12: SILVERTON | B12: -25.727388634278455, 28.29699912151972 | C12: 0.23680556 | D12: 0.30902778 | E12: 0.64583333 | F12: 0.71597222 | G12: 0.79305556
A13: EERSTERUS | B13: -25.720262104484497, 28.30708446350365
A14: WALTOO | B14: -25.716964535181983, 28.32134413848142 | C14: 0.23888889 | D14: 0.31111111 | E14: 0.64791667 | F14: 0.71805556 | G14: 0.79513889
A15: DENNEBOOM | B15: -25.719077472725353, 28.336637070658863 | C15: 0.24027778 | D15: 0.3125 | E15: 0.64930556 | F15: 0.71944444 | G15: 0.79652778
A16: EERSTE FABRIEKE | B16: -25.7221815801619, 28.359894081240192 | C16: 0.24236111 | D16: 0.31458333 | E16: 0.65138889 | F16: 0.72152778 | G16: 0.79861111
A17: MAMELODI GARDENS | B17: -25.727137148700365, 28.38522516947939 | C17: 0.24513889 | D17: 0.31736111 | E17: 0.65416667 | F17: 0.72430556 | G17: 0.80138889
A18: GREENVIEW | B18: -25.73018814715231, 28.406238121914445
A19: PIENAARSPOORT | B19: -25.734672061252613, 28.426968817228143 | C19: 0.25138889 | D19: 0.32083333 | E19: 0.65763889 | F19: 0.72777778 | G19: 0.80486111

Sheet PIEN-to-PTA_Sat
A1: Last Updated: | B1: 45890 | C1: ='PTA-to-PIEN_Weekday'!C1 -> Z2
A2: STATION | B2: COORDINATES | C2: 9100 | D2: 9102 | E2: 9104 | F2: 9116 | G2: 9118
A3: PIENAARSPOORT | B3: -25.734672061252613, 28.426968817228143 | C3: 0.1875 | D3: 0.25833333 | E3: 0.33055556 | F3: 0.66666667 | G3: 0.73680556
A4: GREENVIEW | B4: -25.73018814715231, 28.406238121914445
A5: MAMELODI GARDENS | B5: -25.727137148700365, 28.38522516947939 | C5: 0.19375 | D5: 0.26458333 | E5: 0.33680556 | F5: 0.67291667 | G5: 0.74305556
A6: EERSTE FABRIEKE | B6: -25.7221815801619, 28.359894081240192 | C6: 0.19722222 | D6: 0.26805556 | E6: 0.34027778 | F6: 0.67638889 | G6: 0.74652778
A7: DENNEBOOM | B7: -25.719077472725353, 28.336637070658863 | C7: 0.19930556 | D7: 0.27013889 | E7: 0.34236111 | F7: 0.67847222 | G7: 0.74861111
A8: WALTOO | B8: -25.716950166393737, 28.32134413848142 | C8: 0.20069444 | D8: 0.27152778 | E8: 0.34375 | F8: 0.67986111 | G8: 0.75
A9: EERSTERUS | B9: -25.720262104484497, 28.30708446350365
A10: SILVERTON | B10: -25.727388634278455, 28.29699912151972 | C10: 0.20277778 | D10: 0.27361111 | E10: 0.34583333 | F10: 0.68194444 | G10: 0.75208333
A11: KOEDOESPOORT | B11: -25.72608149772232, 28.27872645216183 | C11: 0.20486111 | D11: 0.27569444 | E11: 0.34791667 | F11: 0.68402778 | G11: 0.75416667
A12: QUEENSWOOD | B12: -25.721853760563217, 28.25178790666072
A13: HARTBEESSPRUIT | B13: -25.746516360305577, 28.2411523995095 | C13: 0.20694444 | D13: 0.27777778 | E13: 0.35 | F13: 0.68611111 | G13: 0.75625
A14: RISSIK | B14: -25.749263370927064, 28.232274866782785 | C14: 0.20972222 | D14: 0.28055556 | E14: 0.35277778 | F14: 0.68888889 | G14: 0.75902778
A15: LOFTUS VERSFELD PARK | B15: -25.754940155678536, 28.22535667426071 | C15: 0.21180556 | D15: 0.28263889 | E15: 0.35486111 | F15: 0.69097222 | G15: 0.76111111
A16: WALKER STREET | B16: -25.76012800529803, 28.213499980098053 | C16: 0.21388889 | D16: 0.28472222 | E16: 0.35694444 | F16: 0.69305556 | G16: 0.76319444
A17: DEVENISH STREET | B17: -25.760571651064055, 28.209966455924803 | C17: 0.21527778 | D17: 0.28611111 | E17: 0.35833333 | F17: 0.69444444 | G17: 0.76458333
A18: MEARS STREET | B18: -25.759836388884576, 28.201559350093763 | C18: 0.21597222 | D18: 0.28680556 | E18: 0.35902778 | F18: 0.69513889 | G18: 0.76527778
A19: PRETORIA | B19: -25.75864361043285, 28.189866445989118 | C19: 0.21875 | D19: 0.28958333 | E19: 0.36180556 | F19: 0.69791667 | G19: 0.76805556

Sheet PTA-to-MAB_Weekday
A1: Last Updated: | B1: 46055 | C1: Z2
A2: STATION | B2: COORDINATES | C2: 1801 | D2: 1803 | E2: 1805 | F2: 1807 | G2: 1809 | H2: 1811 | I2: 1813 | J2: 1815 | K2: 1817 | L2: 1819 | M2: 1827 | N2: 1829 | O2: 1837 | P2: 1831 | Q2: 1833 | R2: 1839 | S2: 1835 | T2: 1845 | U2: 1847 | V2: 1849 | W2: 1851 | X2: 1853 | Y2: 1855 | Z2: 1857 | AA2: 1859 | AB2: 1861 | AC2: 1863 | AD2: 1865
A3: PRETORIA | B3: ='PTA-to-PIEN_Sat'!B3 -> -25.75864361043285, 28.189866445989118 | C3: 0.21666667 | D3: 0.23263889 | E3: 0.24930556 | F3: 0.26527778 | G3: 0.28194444 | H3: 0.29791667 | I3: 0.31458333 | J3: 0.33055556 | K3: 0.34722222 | L3: 0.36319444 | M3: 0.39583333 | N3: 0.44444444 | O3: 0.47013889 | P3: 0.49305556 | Q3: 0.54166667 | R3: 0.56736111 | S3: 0.59027778 | T3: 0.64027778 | U3: 0.65694444 | V3: 0.67291667 | W3: 0.68958333 | X3: 0.70555556 | Y3: 0.72222222 | Z3: 0.73819444 | AA3: 0.75486111 | AB3: 0.77013889 | AC3: 0.80069444 | AD3: 0.8125
A4: PRETORIA-B | B4: -25.756676856613193, 28.185038595618654
A5: BARRACKS | B5: -25.755574101903797, 28.179303473039578
A6: PRETORIA WES | B6: -25.75612607001734, 28.167454033423436 | C6: 0.22083333 | D6: 0.23680556 | E6: 0.25347222 | F6: 0.26944444 | G6: 0.28611111 | H6: 0.30208333 | I6: 0.31875 | J6: 0.33472222 | K6: 0.35138889 | L6: 0.36736111 | M6: 0.4 | N6: 0.44861111 | O6: 0.47430556 | P6: 0.49722222 | Q6: 0.54583333 | R6: 0.57152778 | S6: 0.59444444 | T6: 0.64444444 | U6: 0.66111111 | V6: 0.67708333 | W6: 0.69375 | X6: 0.70972222 | Y6: 0.72638889 | Z6: 0.74236111 | AA6: 0.75902778 | AB6: 0.77430556 | AC6: 0.80486111 | AD6: 0.81666667
A7: MITCHELLSTRAAT | B7: -25.75622307580123, 28.162751428886452
A8: SCHUTTESTRAAT | B8: -25.750415192351678, 28.15981508027586
A9: GOLF | B9: -25.73976641543697, 28.16133154377941
A10: TECHNIKON RANT | B10: -25.732094233731814, 28.167478537946376
A11: HERCULES | B11: -25.724426332570793, 28.16740145328856 | C11: 0.22638889 | D11: 0.24236111 | E11: 0.25902778 | F11: 0.275 | G11: 0.29166667 | H11: 0.30763889 | I11: 0.32430556 | J11: 0.34027778 | K11: 0.35694444 | L11: 0.37291667 | M11: 0.40555556 | N11: 0.45416667 | O11: 0.47986111 | P11: 0.50277778 | Q11: 0.55138889 | R11: 0.57708333 | S11: 0.6 | T11: 0.65 | U11: 0.66666667 | V11: 0.68263889 | W11: 0.69930556 | X11: 0.71527778 | Y11: 0.73194444 | Z11: 0.74791667 | AA11: 0.76458333 | AB11: 0.77986111 | AC11: 0.81041667 | AD11: 0.82222222
A12: DASPOORT | B12: -25.71389154994833, 28.16610216678128
A13: MOUNTAIN VIEW | B13: -25.701154966265122, 28.1710407244521 | C13: 0.22986111 | D13: 0.24583333 | E13: 0.2625 | F13: 0.27847222 | G13: 0.29513889 | H13: 0.31111111 | I13: 0.32777778 | J13: 0.34375 | K13: 0.36041667 | L13: 0.37638889 | M13: 0.40902778 | N13: 0.45763889 | O13: 0.48333333 | P13: 0.50625 | Q13: 0.55486111 | R13: 0.58055556 | S13: 0.60347222 | T13: 0.65347222 | U13: 0.67013889 | V13: 0.68611111 | W13: 0.70277778 | X13: 0.71875 | Y13: 0.73541667 | Z13: 0.75138889 | AA13: 0.76805556 | AB13: 0.78333333 | AC13: 0.81388889 | AD13: 0.82569444
A14: WONDERBOOM | B14: -25.679398283013505, 28.182541636641577
A15: PRETORIA-N | B15: -25.672156912459837, 28.181972182122085 | C15: 0.23472222 | D15: 0.25069444 | E15: 0.26736111 | F15: 0.28333333 | G15: 0.3 | H15: 0.31597222 | I15: 0.33263889 | J15: 0.34861111 | K15: 0.36527778 | L15: 0.38125 | M15: 0.41388889 | N15: 0.4625 | O15: 0.48819444 | P15: 0.51111111 | Q15: 0.55972222 | R15: 0.58541667 | S15: 0.60833333 | T15: 0.65833333 | U15: 0.675 | V15: 0.69097222 | W15: 0.70763889 | X15: 0.72361111 | Y15: 0.74027778 | Z15: 0.75625 | AA15: 0.77291667 | AB15: 0.78819444 | AC15: 0.81875 | AD15: 0.83055556
A16: WOLMERTON | B16: -25.656754583256834, 28.166308537943245 | C16: 0.2375 | D16: 0.25347222 | E16: 0.27013889 | F16: 0.28611111 | G16: 0.30277778 | H16: 0.31875 | I16: 0.33541667 | J16: 0.35138889 | K16: 0.36805556 | L16: 0.38402778 | M16: 0.41666667 | N16: 0.46527778 | O16: 0.49097222 | P16: 0.51388889 | Q16: 0.5625 | R16: 0.58819444 | S16: 0.61111111 | T16: 0.66111111 | U16: 0.67777778 | V16: 0.69375 | W16: 0.71041667 | X16: 0.72638889 | Y16: 0.74305556 | Z16: 0.75902778 | AA16: 0.77569444 | AB16: 0.79097222 | AC16: 0.82152778 | AD16: 0.83333333
A17: WINTERSNEST | B17: -25.646665143468105, 28.128664081235527 | C17: 0.24097222 | D17: 0.25694444 | E17: 0.27361111 | F17: 0.28958333 | G17: 0.30625 | H17: 0.32222222 | I17: 0.33888889 | J17: 0.35486111 | K17: 0.37152778 | L17: 0.3875 | M17: 0.42013889 | N17: 0.46875 | O17: 0.49444444 | P17: 0.51736111 | Q17: 0.56597222 | R17: 0.59166667 | S17: 0.61458333 | T17: 0.66458333 | U17: 0.68125 | V17: 0.69722222 | W17: 0.71388889 | X17: 0.72986111 | Y17: 0.74652778 | Z17: 0.7625 | AA17: 0.77916667 | AB17: 0.79444444 | AC17: 0.825 | AD17: 0.83680556
A18: AKASIABOOM | B18: -25.62343788217021, 28.107351095613126 | C18: 0.24583333 | D18: 0.26180556 | E18: 0.27847222 | F18: 0.29444444 | G18: 0.31111111 | H18: 0.32708333 | I18: 0.34375 | J18: 0.35972222 | K18: 0.37638889 | L18: 0.39236111 | M18: 0.425 | N18: 0.47361111 | O18: 0.49930556 | P18: 0.52222222 | Q18: 0.57083333 | R18: 0.59652778 | S18: 0.61944444 | T18: 0.66944444 | U18: 0.68611111 | V18: 0.70208333 | W18: 0.71875 | X18: 0.73472222 | Y18: 0.75138889 | Z18: 0.76736111 | AA18: 0.78402778 | AB18: 0.79930556 | AC18: 0.82986111 | AD18: 0.84166667
A19: KOPANONG | B19: -25.581315356478292, 28.0903223133063 | C19: 0.24930556 | D19: 0.26527778 | E19: 0.28194444 | F19: 0.29791667 | G19: 0.31458333 | H19: 0.33055556 | I19: 0.34722222 | J19: 0.36319444 | K19: 0.37986111 | L19: 0.39583333 | M19: 0.42847222 | N19: 0.47708333 | O19: 0.50277778 | P19: 0.52569444 | Q19: 0.57430556 | R19: 0.6 | S19: 0.62291667 | T19: 0.67291667 | U19: 0.68958333 | V19: 0.70555556 | W19: 0.72222222 | X19: 0.73819444 | Y19: 0.75486111 | Z19: 0.77083333 | AA19: 0.7875 | AB19: 0.80277778 | AC19: 0.83333333 | AD19: 0.84513889
A20: LEBALENG | B20: -25.541710548406016, 28.076425164924746
A21: SOSHANGUVE | B21: -25.520916877100483, 28.082831418476943
A22: MABOPANE | B22: -25.495963167301053, 28.089659387779985 | C22: 0.25833333 | D22: 0.27430556 | E22: 0.29097222 | F22: 0.30694444 | G22: 0.32361111 | H22: 0.33958333 | I22: 0.35625 | J22: 0.37222222 | K22: 0.38888889 | L22: 0.40486111 | M22: 0.4375 | N22: 0.48611111 | O22: 0.51180556 | P22: 0.53472222 | Q22: 0.58333333 | R22: 0.60902778 | S22: 0.63194444 | T22: 0.68194444 | U22: 0.69861111 | V22: 0.71458333 | W22: 0.73125 | X22: 0.74722222 | Y22: 0.76388889 | Z22: 0.77986111 | AA22: 0.79652778 | AB22: 0.81180556 | AC22: 0.84236111 | AD22: 0.85416667

Sheet MAB-to-PTA_Weekday
A1: Last Updated: | B1: ='PTA-to-MAB_Weekday'!B1 -> 46055 | C1: ='PTA-to-MAB_Weekday'!C1 -> Z2
A2: STATION | B2: COORDINATES | C2: 1800 | D2: 1802 | E2: 1804 | F2: 1806 | G2: 1808 | H2: 1810 | I2: 1812 | J2: 1814 | K2: 1816 | L2: 1818 | M2: 1820 | N2: 1822 | O2: 1824 | P2: 1826 | Q2: 1836 | R2: 1828 | S2: 1830 | T2: 1838 | U2: 1832 | V2: 1834 | W2: 1840 | X2: 1850 | Y2: 1852 | Z2: 1854 | AA2: 1856 | AB2: 1858 | AC2: 1860 | AD2: 1862 | AE2: 1864
A3: MABOPANE | B3: -25.495963167301053, 28.089659387779985 | C3: 0.16805556 | D3: 0.18402778 | E3: 0.20069444 | F3: 0.21666667 | G3: 0.23333333 | H3: 0.24930556 | I3: 0.26597222 | J3: 0.28194444 | K3: 0.29861111 | L3: 0.31458333 | M3: 0.33125 | N3: 0.34722222 | O3: 0.36388889 | P3: 0.39583333 | Q3: 0.42152778 | R3: 0.44444444 | S3: 0.49305556 | T3: 0.51875 | U3: 0.54166667 | V3: 0.59027778 | W3: 0.62152778 | X3: 0.64027778 | Y3: 0.65763889 | Z3: 0.67291667 | AA3: 0.68958333 | AB3: 0.70625 | AC3: 0.72222222 | AD3: 0.73819444 | AE3: 0.75486111
A4: SOSHANGUVE | B4: -25.520916877100483, 28.082831418476943
A5: LEBALENG | B5: -25.541710548406016, 28.076425164924746
A6: KOPANONG | B6: -25.581315356478292, 28.0903223133063 | C6: 0.17638889 | D6: 0.19236111 | E6: 0.20902778 | F6: 0.225 | G6: 0.24166667 | H6: 0.25763889 | I6: 0.27430556 | J6: 0.29027778 | K6: 0.30694444 | L6: 0.32291667 | M6: 0.33958333 | N6: 0.35555556 | O6: 0.37222222 | P6: 0.40416667 | Q6: 0.42986111 | R6: 0.45277778 | S6: 0.50138889 | T6: 0.52708333 | U6: 0.55 | V6: 0.59861111 | W6: 0.62986111 | X6: 0.64861111 | Y6: 0.66597222 | Z6: 0.68125 | AA6: 0.69791667 | AB6: 0.71458333 | AC6: 0.73055556 | AD6: 0.74652778 | AE6: 0.76319444
A7: AKASIABOOM | B7: -25.62343788217021, 28.107351095613126 | C7: 0.18055556 | D7: 0.19652778 | E7: 0.21319444 | F7: 0.22916667 | G7: 0.24583333 | H7: 0.26180556 | I7: 0.27847222 | J7: 0.29444444 | K7: 0.31111111 | L7: 0.32708333 | M7: 0.34375 | N7: 0.35972222 | O7: 0.37638889 | P7: 0.40833333 | Q7: 0.43402778 | R7: 0.45694444 | S7: 0.50555556 | T7: 0.53125 | U7: 0.55416667 | V7: 0.60277778 | W7: 0.63402778 | X7: 0.65277778 | Y7: 0.67013889 | Z7: 0.68541667 | AA7: 0.70208333 | AB7: 0.71875 | AC7: 0.73472222 | AD7: 0.75069444 | AE7: 0.76736111
A8: WINTERSNEST | B8: -25.646665143468105, 28.128664081235527 | C8: 0.18541667 | D8: 0.20138889 | E8: 0.21805556 | F8: 0.23402778 | G8: 0.25069444 | H8: 0.26666667 | I8: 0.28333333 | J8: 0.29930556 | K8: 0.31597222 | L8: 0.33194444 | M8: 0.34861111 | N8: 0.36458333 | O8: 0.38125 | P8: 0.41319444 | Q8: 0.43888889 | R8: 0.46180556 | S8: 0.51041667 | T8: 0.53611111 | U8: 0.55902778 | V8: 0.60763889 | W8: 0.63888889 | X8: 0.65763889 | Y8: 0.675 | Z8: 0.69027778 | AA8: 0.70694444 | AB8: 0.72361111 | AC8: 0.73958333 | AD8: 0.75555556 | AE8: 0.77222222
A9: WOLMERTON | B9: -25.656754583256834, 28.166308537943245 | C9: 0.18958333 | D9: 0.20555556 | E9: 0.22222222 | F9: 0.23819444 | G9: 0.25486111 | H9: 0.27083333 | I9: 0.2875 | J9: 0.30347222 | K9: 0.32013889 | L9: 0.33611111 | M9: 0.35277778 | N9: 0.36875 | O9: 0.38541667 | P9: 0.41736111 | Q9: 0.44305556 | R9: 0.46597222 | S9: 0.51458333 | T9: 0.54027778 | U9: 0.56319444 | V9: 0.61180556 | W9: 0.64305556 | X9: 0.66180556 | Y9: 0.67916667 | Z9: 0.69444444 | AA9: 0.71111111 | AB9: 0.72777778 | AC9: 0.74375 | AD9: 0.75972222 | AE9: 0.77638889
A10: PRETORIA-N | B10: -25.672156912459837, 28.181972182122085 | C10: 0.19236111 | D10: 0.20833333 | E10: 0.225 | F10: 0.24097222 | G10: 0.25763889 | H10: 0.27361111 | I10: 0.29027778 | J10: 0.30625 | K10: 0.32291667 | L10: 0.33888889 | M10: 0.35555556 | N10: 0.37152778 | O10: 0.38819444 | P10: 0.42013889 | Q10: 0.44583333 | R10: 0.46875 | S10: 0.51736111 | T10: 0.54305556 | U10: 0.56597222 | V10: 0.61458333 | W10: 0.64583333 | X10: 0.66458333 | Y10: 0.68194444 | Z10: 0.69722222 | AA10: 0.71388889 | AB10: 0.73055556 | AC10: 0.74652778 | AD10: 0.7625 | AE10: 0.77916667
A11: WONDERBOOM | B11: -25.679398283013505, 28.182541636641577
